[2025-01-17T22:21:44.480+0000] {local_task_job_runner.py:123} INFO - ::group::Pre task execution logs
[2025-01-17T22:21:44.500+0000] {taskinstance.py:2613} INFO - Dependencies all met for dep_context=non-requeueable deps ti=<TaskInstance: spaceflight_data_ingest_v2.fetch_events manual__2025-01-17T22:14:24.591389+00:00 [queued]>
[2025-01-17T22:21:44.511+0000] {taskinstance.py:2613} INFO - Dependencies all met for dep_context=requeueable deps ti=<TaskInstance: spaceflight_data_ingest_v2.fetch_events manual__2025-01-17T22:14:24.591389+00:00 [queued]>
[2025-01-17T22:21:44.512+0000] {taskinstance.py:2866} INFO - Starting attempt 2 of 3
[2025-01-17T22:21:44.529+0000] {taskinstance.py:2889} INFO - Executing <Task(PythonOperator): fetch_events> on 2025-01-17 22:14:24.591389+00:00
[2025-01-17T22:21:44.540+0000] {warnings.py:112} WARNING - /home/***/.local/lib/python3.12/site-packages/***/task/task_runner/standard_task_runner.py:70: DeprecationWarning: This process (pid=555) is multi-threaded, use of fork() may lead to deadlocks in the child.
  pid = os.fork()

[2025-01-17T22:21:44.542+0000] {standard_task_runner.py:72} INFO - Started process 557 to run task
[2025-01-17T22:21:44.542+0000] {standard_task_runner.py:104} INFO - Running: ['***', 'tasks', 'run', 'spaceflight_data_ingest_v2', 'fetch_events', 'manual__2025-01-17T22:14:24.591389+00:00', '--job-id', '101', '--raw', '--subdir', 'DAGS_FOLDER/spaceflight_data_ingest_v2.py', '--cfg-path', '/tmp/tmp53k76vu8']
[2025-01-17T22:21:44.543+0000] {standard_task_runner.py:105} INFO - Job 101: Subtask fetch_events
[2025-01-17T22:21:44.596+0000] {task_command.py:467} INFO - Running <TaskInstance: spaceflight_data_ingest_v2.fetch_events manual__2025-01-17T22:14:24.591389+00:00 [running]> on host 59ff16f1d4fb
[2025-01-17T22:21:44.922+0000] {taskinstance.py:3132} INFO - Exporting env vars: AIRFLOW_CTX_DAG_OWNER='***' AIRFLOW_CTX_DAG_ID='spaceflight_data_ingest_v2' AIRFLOW_CTX_TASK_ID='fetch_events' AIRFLOW_CTX_EXECUTION_DATE='2025-01-17T22:14:24.591389+00:00' AIRFLOW_CTX_TRY_NUMBER='2' AIRFLOW_CTX_DAG_RUN_ID='manual__2025-01-17T22:14:24.591389+00:00'
[2025-01-17T22:21:44.923+0000] {logging_mixin.py:190} INFO - Task instance is in running state
[2025-01-17T22:21:44.924+0000] {logging_mixin.py:190} INFO -  Previous state of the Task instance: queued
[2025-01-17T22:21:44.924+0000] {logging_mixin.py:190} INFO - Current task name:fetch_events state:running start_date:2025-01-17 22:21:44.501543+00:00
[2025-01-17T22:21:44.924+0000] {logging_mixin.py:190} INFO - Dag name:spaceflight_data_ingest_v2 and current dag run status:running
[2025-01-17T22:21:44.924+0000] {taskinstance.py:731} INFO - ::endgroup::
[2025-01-17T22:21:45.181+0000] {spaceflight_data_ingest_v2.py:77} ERROR - Error al obtener events: 404
[2025-01-17T22:22:40.250+0000] {spaceflight_data_ingest_v2.py:77} ERROR - Error al obtener events: 404
[2025-01-17T22:22:49.865+0000] {local_task_job_runner.py:346} WARNING - State of this instance has been externally set to restarting. Terminating instance.
[2025-01-17T22:22:49.866+0000] {local_task_job_runner.py:245} INFO - ::endgroup::
[2025-01-17T22:22:49.867+0000] {process_utils.py:132} INFO - Sending 15 to group 557. PIDs of all processes in the group: [557]
[2025-01-17T22:22:49.867+0000] {process_utils.py:87} INFO - Sending the signal 15 to group 557
[2025-01-17T22:22:49.868+0000] {taskinstance.py:3093} ERROR - Received SIGTERM. Terminating subprocesses.
[2025-01-17T22:22:49.879+0000] {taskinstance.py:3311} ERROR - Task failed with exception
Traceback (most recent call last):
  File "/home/airflow/.local/lib/python3.12/site-packages/airflow/models/taskinstance.py", line 767, in _execute_task
    result = _execute_callable(context=context, **execute_callable_kwargs)
             ^^^^^^^^^^^^^^^^^^^^^^^^^^^^^^^^^^^^^^^^^^^^^^^^^^^^^^^^^^^^^
  File "/home/airflow/.local/lib/python3.12/site-packages/airflow/models/taskinstance.py", line 733, in _execute_callable
    return ExecutionCallableRunner(
           ^^^^^^^^^^^^^^^^^^^^^^^^
  File "/home/airflow/.local/lib/python3.12/site-packages/airflow/utils/operator_helpers.py", line 252, in run
    return self.func(*args, **kwargs)
           ^^^^^^^^^^^^^^^^^^^^^^^^^^
  File "/home/airflow/.local/lib/python3.12/site-packages/airflow/models/baseoperator.py", line 422, in wrapper
    return func(self, *args, **kwargs)
           ^^^^^^^^^^^^^^^^^^^^^^^^^^^
  File "/home/airflow/.local/lib/python3.12/site-packages/airflow/operators/python.py", line 238, in execute
    return_value = self.execute_callable()
                   ^^^^^^^^^^^^^^^^^^^^^^^
  File "/home/airflow/.local/lib/python3.12/site-packages/airflow/operators/python.py", line 256, in execute_callable
    return runner.run(*self.op_args, **self.op_kwargs)
           ^^^^^^^^^^^^^^^^^^^^^^^^^^^^^^^^^^^^^^^^^^^
  File "/home/airflow/.local/lib/python3.12/site-packages/airflow/utils/operator_helpers.py", line 252, in run
    return self.func(*args, **kwargs)
           ^^^^^^^^^^^^^^^^^^^^^^^^^^
  File "/opt/airflow/dags/spaceflight_data_ingest_v2.py", line 98, in fetch_events
    fetch_data(
  File "/opt/airflow/dags/spaceflight_data_ingest_v2.py", line 78, in fetch_data
    time.sleep(60)
  File "/home/airflow/.local/lib/python3.12/site-packages/airflow/models/taskinstance.py", line 3095, in signal_handler
    raise AirflowTaskTerminated("Task received SIGTERM signal")
airflow.exceptions.AirflowTaskTerminated: Task received SIGTERM signal
[2025-01-17T22:22:49.884+0000] {logging_mixin.py:190} INFO - Task instance in failure state
[2025-01-17T22:22:49.884+0000] {logging_mixin.py:190} INFO - Task start:2025-01-17 22:21:44.501543+00:00 end:2025-01-17 22:22:49.883651+00:00 duration:65.382108
[2025-01-17T22:22:49.884+0000] {logging_mixin.py:190} INFO - Task:<Task(PythonOperator): fetch_events> dag:<DAG: spaceflight_data_ingest_v2> dagrun:<DagRun spaceflight_data_ingest_v2 @ 2025-01-17 22:14:24.591389+00:00: manual__2025-01-17T22:14:24.591389+00:00, state:running, queued_at: 2025-01-17 22:14:24.604201+00:00. externally triggered: True>
[2025-01-17T22:22:49.885+0000] {logging_mixin.py:190} INFO - Failure caused by Task received SIGTERM signal
[2025-01-17T22:22:49.885+0000] {taskinstance.py:1225} INFO - Marking task as UP_FOR_RETRY. dag_id=spaceflight_data_ingest_v2, task_id=fetch_events, run_id=manual__2025-01-17T22:14:24.591389+00:00, execution_date=20250117T221424, start_date=20250117T222144, end_date=20250117T222249
[2025-01-17T22:22:49.901+0000] {taskinstance.py:340} INFO - ::group::Post task execution logs
[2025-01-17T22:22:49.961+0000] {process_utils.py:80} INFO - Process psutil.Process(pid=557, status='terminated', exitcode=2, started='22:21:44') (557) terminated with exit code 2
