[2025-01-17T18:28:25.161+0000] {local_task_job_runner.py:123} INFO - ::group::Pre task execution logs
[2025-01-17T18:28:25.181+0000] {taskinstance.py:2613} INFO - Dependencies all met for dep_context=non-requeueable deps ti=<TaskInstance: DAG_ELT_PostgreSQL.check_table manual__2025-01-17T18:26:15.245072+00:00 [queued]>
[2025-01-17T18:28:25.191+0000] {taskinstance.py:2613} INFO - Dependencies all met for dep_context=requeueable deps ti=<TaskInstance: DAG_ELT_PostgreSQL.check_table manual__2025-01-17T18:26:15.245072+00:00 [queued]>
[2025-01-17T18:28:25.192+0000] {taskinstance.py:2866} INFO - Starting attempt 2 of 2
[2025-01-17T18:28:25.206+0000] {taskinstance.py:2889} INFO - Executing <Task(PostgresOperator): check_table> on 2025-01-17 18:26:15.245072+00:00
[2025-01-17T18:28:25.215+0000] {warnings.py:112} WARNING - /home/***/.local/lib/python3.12/site-packages/***/task/task_runner/standard_task_runner.py:70: DeprecationWarning: This process (pid=3473) is multi-threaded, use of fork() may lead to deadlocks in the child.
  pid = os.fork()

[2025-01-17T18:28:25.216+0000] {standard_task_runner.py:72} INFO - Started process 3475 to run task
[2025-01-17T18:28:25.217+0000] {standard_task_runner.py:104} INFO - Running: ['***', 'tasks', 'run', 'DAG_ELT_PostgreSQL', 'check_table', 'manual__2025-01-17T18:26:15.245072+00:00', '--job-id', '47', '--raw', '--subdir', 'DAGS_FOLDER/ETL_PostgreSQL.py', '--cfg-path', '/tmp/tmpdeb0gb_3']
[2025-01-17T18:28:25.217+0000] {standard_task_runner.py:105} INFO - Job 47: Subtask check_table
[2025-01-17T18:28:25.260+0000] {task_command.py:467} INFO - Running <TaskInstance: DAG_ELT_PostgreSQL.check_table manual__2025-01-17T18:26:15.245072+00:00 [running]> on host 59ff16f1d4fb
[2025-01-17T18:28:25.554+0000] {taskinstance.py:3132} INFO - Exporting env vars: AIRFLOW_CTX_DAG_OWNER='Wilfrido Rondon' AIRFLOW_CTX_DAG_ID='DAG_ELT_PostgreSQL' AIRFLOW_CTX_TASK_ID='check_table' AIRFLOW_CTX_EXECUTION_DATE='2025-01-17T18:26:15.245072+00:00' AIRFLOW_CTX_TRY_NUMBER='2' AIRFLOW_CTX_DAG_RUN_ID='manual__2025-01-17T18:26:15.245072+00:00'
[2025-01-17T18:28:25.555+0000] {logging_mixin.py:190} INFO - Task instance is in running state
[2025-01-17T18:28:25.555+0000] {logging_mixin.py:190} INFO -  Previous state of the Task instance: queued
[2025-01-17T18:28:25.556+0000] {logging_mixin.py:190} INFO - Current task name:check_table state:running start_date:2025-01-17 18:28:25.181711+00:00
[2025-01-17T18:28:25.556+0000] {logging_mixin.py:190} INFO - Dag name:DAG_ELT_PostgreSQL and current dag run status:running
[2025-01-17T18:28:25.556+0000] {taskinstance.py:731} INFO - ::endgroup::
[2025-01-17T18:28:25.556+0000] {sql.py:278} INFO - Executing: CREATE TABLE IF NOT EXISTS sales_db (
    DateProcees datetime not null,
    store VARCHAR(255) NOT NULL,
    sales float not null 
   
);
[2025-01-17T18:28:25.565+0000] {base.py:84} INFO - Retrieving connection 'postgres_conn_local'
[2025-01-17T18:28:25.573+0000] {base.py:84} INFO - Retrieving connection 'postgres_conn_local'
[2025-01-17T18:28:25.610+0000] {sql.py:553} INFO - Running statement: CREATE TABLE IF NOT EXISTS sales_db (
    DateProcees datetime not null,
    store VARCHAR(255) NOT NULL,
    sales float not null 
   
);, parameters: None
[2025-01-17T18:28:25.613+0000] {taskinstance.py:3311} ERROR - Task failed with exception
Traceback (most recent call last):
  File "/home/airflow/.local/lib/python3.12/site-packages/airflow/models/taskinstance.py", line 767, in _execute_task
    result = _execute_callable(context=context, **execute_callable_kwargs)
             ^^^^^^^^^^^^^^^^^^^^^^^^^^^^^^^^^^^^^^^^^^^^^^^^^^^^^^^^^^^^^
  File "/home/airflow/.local/lib/python3.12/site-packages/airflow/models/taskinstance.py", line 733, in _execute_callable
    return ExecutionCallableRunner(
           ^^^^^^^^^^^^^^^^^^^^^^^^
  File "/home/airflow/.local/lib/python3.12/site-packages/airflow/utils/operator_helpers.py", line 252, in run
    return self.func(*args, **kwargs)
           ^^^^^^^^^^^^^^^^^^^^^^^^^^
  File "/home/airflow/.local/lib/python3.12/site-packages/airflow/models/baseoperator.py", line 422, in wrapper
    return func(self, *args, **kwargs)
           ^^^^^^^^^^^^^^^^^^^^^^^^^^^
  File "/home/airflow/.local/lib/python3.12/site-packages/airflow/providers/common/sql/operators/sql.py", line 284, in execute
    output = hook.run(
             ^^^^^^^^^
  File "/home/airflow/.local/lib/python3.12/site-packages/airflow/providers/common/sql/hooks/sql.py", line 498, in run
    self._run_command(cur, sql_statement, parameters)
  File "/home/airflow/.local/lib/python3.12/site-packages/airflow/providers/common/sql/hooks/sql.py", line 558, in _run_command
    cur.execute(sql_statement)
psycopg2.errors.UndefinedObject: type "datetime" does not exist
LINE 2:     DateProcees datetime not null,
                        ^

[2025-01-17T18:28:25.622+0000] {logging_mixin.py:190} INFO - Task instance in failure state
[2025-01-17T18:28:25.622+0000] {logging_mixin.py:190} INFO - Task start:2025-01-17 18:28:25.181711+00:00 end:2025-01-17 18:28:25.621792+00:00 duration:0.440081
[2025-01-17T18:28:25.622+0000] {logging_mixin.py:190} INFO - Task:<Task(PostgresOperator): check_table> dag:<DAG: DAG_ELT_PostgreSQL> dagrun:<DagRun DAG_ELT_PostgreSQL @ 2025-01-17 18:26:15.245072+00:00: manual__2025-01-17T18:26:15.245072+00:00, state:running, queued_at: 2025-01-17 18:26:15.254531+00:00. externally triggered: True>
[2025-01-17T18:28:25.622+0000] {logging_mixin.py:190} INFO - Failure caused by type "datetime" does not exist
LINE 2:     DateProcees datetime not null,
                        ^
[2025-01-17T18:28:25.623+0000] {taskinstance.py:1225} INFO - Marking task as FAILED. dag_id=DAG_ELT_PostgreSQL, task_id=check_table, run_id=manual__2025-01-17T18:26:15.245072+00:00, execution_date=20250117T182615, start_date=20250117T182825, end_date=20250117T182825
[2025-01-17T18:28:25.633+0000] {taskinstance.py:340} INFO - ::group::Post task execution logs
[2025-01-17T18:28:25.634+0000] {standard_task_runner.py:124} ERROR - Failed to execute job 47 for task check_table (type "datetime" does not exist
LINE 2:     DateProcees datetime not null,
                        ^
; 3475)
Traceback (most recent call last):
  File "/home/airflow/.local/lib/python3.12/site-packages/airflow/task/task_runner/standard_task_runner.py", line 117, in _start_by_fork
    ret = args.func(args, dag=self.dag)
          ^^^^^^^^^^^^^^^^^^^^^^^^^^^^^
  File "/home/airflow/.local/lib/python3.12/site-packages/airflow/cli/cli_config.py", line 49, in command
    return func(*args, **kwargs)
           ^^^^^^^^^^^^^^^^^^^^^
  File "/home/airflow/.local/lib/python3.12/site-packages/airflow/utils/cli.py", line 116, in wrapper
    return f(*args, **kwargs)
           ^^^^^^^^^^^^^^^^^^
  File "/home/airflow/.local/lib/python3.12/site-packages/airflow/cli/commands/task_command.py", line 483, in task_run
    task_return_code = _run_task_by_selected_method(args, _dag, ti)
                       ^^^^^^^^^^^^^^^^^^^^^^^^^^^^^^^^^^^^^^^^^^^^
  File "/home/airflow/.local/lib/python3.12/site-packages/airflow/cli/commands/task_command.py", line 256, in _run_task_by_selected_method
    return _run_raw_task(args, ti)
           ^^^^^^^^^^^^^^^^^^^^^^^
  File "/home/airflow/.local/lib/python3.12/site-packages/airflow/cli/commands/task_command.py", line 341, in _run_raw_task
    return ti._run_raw_task(
           ^^^^^^^^^^^^^^^^^
  File "/home/airflow/.local/lib/python3.12/site-packages/airflow/utils/session.py", line 97, in wrapper
    return func(*args, session=session, **kwargs)
           ^^^^^^^^^^^^^^^^^^^^^^^^^^^^^^^^^^^^^^
  File "/home/airflow/.local/lib/python3.12/site-packages/airflow/models/taskinstance.py", line 3005, in _run_raw_task
    return _run_raw_task(
           ^^^^^^^^^^^^^^
  File "/home/airflow/.local/lib/python3.12/site-packages/airflow/models/taskinstance.py", line 273, in _run_raw_task
    TaskInstance._execute_task_with_callbacks(
  File "/home/airflow/.local/lib/python3.12/site-packages/airflow/models/taskinstance.py", line 3159, in _execute_task_with_callbacks
    result = self._execute_task(context, task_orig)
             ^^^^^^^^^^^^^^^^^^^^^^^^^^^^^^^^^^^^^^
  File "/home/airflow/.local/lib/python3.12/site-packages/airflow/models/taskinstance.py", line 3183, in _execute_task
    return _execute_task(self, context, task_orig)
           ^^^^^^^^^^^^^^^^^^^^^^^^^^^^^^^^^^^^^^^
  File "/home/airflow/.local/lib/python3.12/site-packages/airflow/models/taskinstance.py", line 767, in _execute_task
    result = _execute_callable(context=context, **execute_callable_kwargs)
             ^^^^^^^^^^^^^^^^^^^^^^^^^^^^^^^^^^^^^^^^^^^^^^^^^^^^^^^^^^^^^
  File "/home/airflow/.local/lib/python3.12/site-packages/airflow/models/taskinstance.py", line 733, in _execute_callable
    return ExecutionCallableRunner(
           ^^^^^^^^^^^^^^^^^^^^^^^^
  File "/home/airflow/.local/lib/python3.12/site-packages/airflow/utils/operator_helpers.py", line 252, in run
    return self.func(*args, **kwargs)
           ^^^^^^^^^^^^^^^^^^^^^^^^^^
  File "/home/airflow/.local/lib/python3.12/site-packages/airflow/models/baseoperator.py", line 422, in wrapper
    return func(self, *args, **kwargs)
           ^^^^^^^^^^^^^^^^^^^^^^^^^^^
  File "/home/airflow/.local/lib/python3.12/site-packages/airflow/providers/common/sql/operators/sql.py", line 284, in execute
    output = hook.run(
             ^^^^^^^^^
  File "/home/airflow/.local/lib/python3.12/site-packages/airflow/providers/common/sql/hooks/sql.py", line 498, in run
    self._run_command(cur, sql_statement, parameters)
  File "/home/airflow/.local/lib/python3.12/site-packages/airflow/providers/common/sql/hooks/sql.py", line 558, in _run_command
    cur.execute(sql_statement)
psycopg2.errors.UndefinedObject: type "datetime" does not exist
LINE 2:     DateProcees datetime not null,
                        ^

[2025-01-17T18:28:25.687+0000] {local_task_job_runner.py:266} INFO - Task exited with return code 1
[2025-01-17T18:28:25.712+0000] {taskinstance.py:3895} INFO - 0 downstream tasks scheduled from follow-on schedule check
[2025-01-17T18:28:25.718+0000] {local_task_job_runner.py:245} INFO - ::endgroup::
