[2025-01-17T21:15:00.267+0000] {local_task_job_runner.py:123} INFO - ::group::Pre task execution logs
[2025-01-17T21:15:00.284+0000] {taskinstance.py:2613} INFO - Dependencies all met for dep_context=non-requeueable deps ti=<TaskInstance: spaceflight_data_ingest_v2.fetch_events manual__2025-01-17T21:04:51.092992+00:00 [queued]>
[2025-01-17T21:15:00.294+0000] {taskinstance.py:2613} INFO - Dependencies all met for dep_context=requeueable deps ti=<TaskInstance: spaceflight_data_ingest_v2.fetch_events manual__2025-01-17T21:04:51.092992+00:00 [queued]>
[2025-01-17T21:15:00.294+0000] {taskinstance.py:2866} INFO - Starting attempt 2 of 2
[2025-01-17T21:15:00.310+0000] {taskinstance.py:2889} INFO - Executing <Task(PythonOperator): fetch_events> on 2025-01-17 21:04:51.092992+00:00
[2025-01-17T21:15:00.320+0000] {warnings.py:112} WARNING - /home/***/.local/lib/python3.12/site-packages/***/task/task_runner/standard_task_runner.py:70: DeprecationWarning: This process (pid=1050) is multi-threaded, use of fork() may lead to deadlocks in the child.
  pid = os.fork()

[2025-01-17T21:15:00.321+0000] {standard_task_runner.py:72} INFO - Started process 1052 to run task
[2025-01-17T21:15:00.321+0000] {standard_task_runner.py:104} INFO - Running: ['***', 'tasks', 'run', 'spaceflight_data_ingest_v2', 'fetch_events', 'manual__2025-01-17T21:04:51.092992+00:00', '--job-id', '78', '--raw', '--subdir', 'DAGS_FOLDER/spaceflight_data_ingest_v2.py', '--cfg-path', '/tmp/tmprw7uppyh']
[2025-01-17T21:15:00.322+0000] {standard_task_runner.py:105} INFO - Job 78: Subtask fetch_events
[2025-01-17T21:15:00.367+0000] {task_command.py:467} INFO - Running <TaskInstance: spaceflight_data_ingest_v2.fetch_events manual__2025-01-17T21:04:51.092992+00:00 [running]> on host 59ff16f1d4fb
[2025-01-17T21:15:00.440+0000] {taskinstance.py:3132} INFO - Exporting env vars: AIRFLOW_CTX_DAG_OWNER='***' AIRFLOW_CTX_DAG_ID='spaceflight_data_ingest_v2' AIRFLOW_CTX_TASK_ID='fetch_events' AIRFLOW_CTX_EXECUTION_DATE='2025-01-17T21:04:51.092992+00:00' AIRFLOW_CTX_TRY_NUMBER='2' AIRFLOW_CTX_DAG_RUN_ID='manual__2025-01-17T21:04:51.092992+00:00'
[2025-01-17T21:15:00.441+0000] {logging_mixin.py:190} INFO - Task instance is in running state
[2025-01-17T21:15:00.441+0000] {logging_mixin.py:190} INFO -  Previous state of the Task instance: queued
[2025-01-17T21:15:00.441+0000] {logging_mixin.py:190} INFO - Current task name:fetch_events state:running start_date:2025-01-17 21:15:00.285123+00:00
[2025-01-17T21:15:00.442+0000] {logging_mixin.py:190} INFO - Dag name:spaceflight_data_ingest_v2 and current dag run status:running
[2025-01-17T21:15:00.442+0000] {taskinstance.py:731} INFO - ::endgroup::
[2025-01-17T21:15:00.442+0000] {taskinstance.py:3311} ERROR - Task failed with exception
Traceback (most recent call last):
  File "/home/airflow/.local/lib/python3.12/site-packages/airflow/models/taskinstance.py", line 767, in _execute_task
    result = _execute_callable(context=context, **execute_callable_kwargs)
             ^^^^^^^^^^^^^^^^^^^^^^^^^^^^^^^^^^^^^^^^^^^^^^^^^^^^^^^^^^^^^
  File "/home/airflow/.local/lib/python3.12/site-packages/airflow/models/taskinstance.py", line 733, in _execute_callable
    return ExecutionCallableRunner(
           ^^^^^^^^^^^^^^^^^^^^^^^^
  File "/home/airflow/.local/lib/python3.12/site-packages/airflow/utils/operator_helpers.py", line 252, in run
    return self.func(*args, **kwargs)
           ^^^^^^^^^^^^^^^^^^^^^^^^^^
  File "/home/airflow/.local/lib/python3.12/site-packages/airflow/models/baseoperator.py", line 422, in wrapper
    return func(self, *args, **kwargs)
           ^^^^^^^^^^^^^^^^^^^^^^^^^^^
  File "/home/airflow/.local/lib/python3.12/site-packages/airflow/operators/python.py", line 238, in execute
    return_value = self.execute_callable()
                   ^^^^^^^^^^^^^^^^^^^^^^^
  File "/home/airflow/.local/lib/python3.12/site-packages/airflow/operators/python.py", line 256, in execute_callable
    return runner.run(*self.op_args, **self.op_kwargs)
           ^^^^^^^^^^^^^^^^^^^^^^^^^^^^^^^^^^^^^^^^^^^
  File "/home/airflow/.local/lib/python3.12/site-packages/airflow/utils/operator_helpers.py", line 252, in run
    return self.func(*args, **kwargs)
           ^^^^^^^^^^^^^^^^^^^^^^^^^^
  File "/opt/airflow/dags/spaceflight_data_ingest_v2.py", line 96, in fetch_events
    "api_key": API_KEY,
               ^^^^^^^
NameError: name 'API_KEY' is not defined
[2025-01-17T21:15:00.453+0000] {logging_mixin.py:190} INFO - Task instance in failure state
[2025-01-17T21:15:00.453+0000] {logging_mixin.py:190} INFO - Task start:2025-01-17 21:15:00.285123+00:00 end:2025-01-17 21:15:00.452753+00:00 duration:0.16763
[2025-01-17T21:15:00.454+0000] {logging_mixin.py:190} INFO - Task:<Task(PythonOperator): fetch_events> dag:<DAG: spaceflight_data_ingest_v2> dagrun:<DagRun spaceflight_data_ingest_v2 @ 2025-01-17 21:04:51.092992+00:00: manual__2025-01-17T21:04:51.092992+00:00, state:running, queued_at: 2025-01-17 21:04:51.116933+00:00. externally triggered: True>
[2025-01-17T21:15:00.454+0000] {logging_mixin.py:190} INFO - Failure caused by name 'API_KEY' is not defined
[2025-01-17T21:15:00.454+0000] {taskinstance.py:1225} INFO - Marking task as FAILED. dag_id=spaceflight_data_ingest_v2, task_id=fetch_events, run_id=manual__2025-01-17T21:04:51.092992+00:00, execution_date=20250117T210451, start_date=20250117T211500, end_date=20250117T211500
[2025-01-17T21:15:00.466+0000] {taskinstance.py:340} INFO - ::group::Post task execution logs
[2025-01-17T21:15:00.467+0000] {standard_task_runner.py:124} ERROR - Failed to execute job 78 for task fetch_events (name 'API_KEY' is not defined; 1052)
Traceback (most recent call last):
  File "/home/airflow/.local/lib/python3.12/site-packages/airflow/task/task_runner/standard_task_runner.py", line 117, in _start_by_fork
    ret = args.func(args, dag=self.dag)
          ^^^^^^^^^^^^^^^^^^^^^^^^^^^^^
  File "/home/airflow/.local/lib/python3.12/site-packages/airflow/cli/cli_config.py", line 49, in command
    return func(*args, **kwargs)
           ^^^^^^^^^^^^^^^^^^^^^
  File "/home/airflow/.local/lib/python3.12/site-packages/airflow/utils/cli.py", line 116, in wrapper
    return f(*args, **kwargs)
           ^^^^^^^^^^^^^^^^^^
  File "/home/airflow/.local/lib/python3.12/site-packages/airflow/cli/commands/task_command.py", line 483, in task_run
    task_return_code = _run_task_by_selected_method(args, _dag, ti)
                       ^^^^^^^^^^^^^^^^^^^^^^^^^^^^^^^^^^^^^^^^^^^^
  File "/home/airflow/.local/lib/python3.12/site-packages/airflow/cli/commands/task_command.py", line 256, in _run_task_by_selected_method
    return _run_raw_task(args, ti)
           ^^^^^^^^^^^^^^^^^^^^^^^
  File "/home/airflow/.local/lib/python3.12/site-packages/airflow/cli/commands/task_command.py", line 341, in _run_raw_task
    return ti._run_raw_task(
           ^^^^^^^^^^^^^^^^^
  File "/home/airflow/.local/lib/python3.12/site-packages/airflow/utils/session.py", line 97, in wrapper
    return func(*args, session=session, **kwargs)
           ^^^^^^^^^^^^^^^^^^^^^^^^^^^^^^^^^^^^^^
  File "/home/airflow/.local/lib/python3.12/site-packages/airflow/models/taskinstance.py", line 3005, in _run_raw_task
    return _run_raw_task(
           ^^^^^^^^^^^^^^
  File "/home/airflow/.local/lib/python3.12/site-packages/airflow/models/taskinstance.py", line 273, in _run_raw_task
    TaskInstance._execute_task_with_callbacks(
  File "/home/airflow/.local/lib/python3.12/site-packages/airflow/models/taskinstance.py", line 3159, in _execute_task_with_callbacks
    result = self._execute_task(context, task_orig)
             ^^^^^^^^^^^^^^^^^^^^^^^^^^^^^^^^^^^^^^
  File "/home/airflow/.local/lib/python3.12/site-packages/airflow/models/taskinstance.py", line 3183, in _execute_task
    return _execute_task(self, context, task_orig)
           ^^^^^^^^^^^^^^^^^^^^^^^^^^^^^^^^^^^^^^^
  File "/home/airflow/.local/lib/python3.12/site-packages/airflow/models/taskinstance.py", line 767, in _execute_task
    result = _execute_callable(context=context, **execute_callable_kwargs)
             ^^^^^^^^^^^^^^^^^^^^^^^^^^^^^^^^^^^^^^^^^^^^^^^^^^^^^^^^^^^^^
  File "/home/airflow/.local/lib/python3.12/site-packages/airflow/models/taskinstance.py", line 733, in _execute_callable
    return ExecutionCallableRunner(
           ^^^^^^^^^^^^^^^^^^^^^^^^
  File "/home/airflow/.local/lib/python3.12/site-packages/airflow/utils/operator_helpers.py", line 252, in run
    return self.func(*args, **kwargs)
           ^^^^^^^^^^^^^^^^^^^^^^^^^^
  File "/home/airflow/.local/lib/python3.12/site-packages/airflow/models/baseoperator.py", line 422, in wrapper
    return func(self, *args, **kwargs)
           ^^^^^^^^^^^^^^^^^^^^^^^^^^^
  File "/home/airflow/.local/lib/python3.12/site-packages/airflow/operators/python.py", line 238, in execute
    return_value = self.execute_callable()
                   ^^^^^^^^^^^^^^^^^^^^^^^
  File "/home/airflow/.local/lib/python3.12/site-packages/airflow/operators/python.py", line 256, in execute_callable
    return runner.run(*self.op_args, **self.op_kwargs)
           ^^^^^^^^^^^^^^^^^^^^^^^^^^^^^^^^^^^^^^^^^^^
  File "/home/airflow/.local/lib/python3.12/site-packages/airflow/utils/operator_helpers.py", line 252, in run
    return self.func(*args, **kwargs)
           ^^^^^^^^^^^^^^^^^^^^^^^^^^
  File "/opt/airflow/dags/spaceflight_data_ingest_v2.py", line 96, in fetch_events
    "api_key": API_KEY,
               ^^^^^^^
NameError: name 'API_KEY' is not defined
[2025-01-17T21:15:00.499+0000] {local_task_job_runner.py:266} INFO - Task exited with return code 1
[2025-01-17T21:15:00.522+0000] {taskinstance.py:3895} INFO - 0 downstream tasks scheduled from follow-on schedule check
[2025-01-17T21:15:00.526+0000] {local_task_job_runner.py:245} INFO - ::endgroup::
